<?xml version="1.0" encoding="utf-8"?>
<!-- This URDF was automatically created by SolidWorks to URDF Exporter! Originally created by Stephen Brawner (brawner@gmail.com) 
     Commit Version: 1.6.0-4-g7f85cfe  Build Version: 1.6.7995.38578
     For more information, please see http://wiki.ros.org/sw_urdf_exporter -->
<robot
  name="OpenLoog">
  <mujoco>
    <compiler
    	meshdir="/home/pi/Downloads/OmniBotCtrl/resources/loong/meshes/"
    	balanceinertia="true"
    	discardvisual="false" />
  </mujoco>
  <link
    name="base_link">
    <inertial>
      <origin
        xyz="-0.0056641 -0.0013367 0.23829"
        rpy="0 0 0" />
      <mass
        value="22.447" />
      <inertia
        ixx="0.3742"
        ixy="0"
        ixz="0"
        iyy="0.27691"
        iyz="0"
        izz="0.22104" />
    </inertial>
    <visual>
      <origin
        xyz="0 0 0"
        rpy="0 0 0" />
      <geometry>
        <mesh
          filename="/home/pi/Downloads/OmniBotCtrl/resources/loong/meshes/base_link.STL" />
      </geometry>
      <material
        name="">
        <color
          rgba="0.75294 0.75294 0.75294 1" />
      </material>
    </visual>
    <collision>
      <origin
        xyz="0 0 0"
        rpy="0 0 0" />
      <geometry>
        <mesh
          filename="/home/pi/Downloads/OmniBotCtrl/resources/loong/meshes/base_link.STL" />
      </geometry>
    </collision>
  </link>
  <link
    name="Link_head_yaw">
    <inertial>
      <origin
        xyz="4.6974E-12 -0.0020814 0.044801"
        rpy="0 0 0" />
      <mass
        value="0.84249" />
      <inertia
        ixx="0.000629"
        ixy="-1.2848E-14"
        ixz="1.5461E-10"
        iyy="0.0007003"
        iyz="6.5E-06"
        izz="0.0005541" />
    </inertial>
    <visual>
      <origin
        xyz="0 0 0"
        rpy="0 0 0" />
      <geometry>
        <mesh
          filename="/home/pi/Downloads/OmniBotCtrl/resources/loong/meshes/Link_head_yaw.STL" />
      </geometry>
      <material
        name="">
        <color
          rgba="0.89804 0.91765 0.92941 1" />
      </material>
    </visual>
    <collision>
      <origin
        xyz="0 0 0"
        rpy="0 0 0" />
      <geometry>
        <mesh
          filename="/home/pi/Downloads/OmniBotCtrl/resources/loong/meshes/Link_head_yaw.STL" />
      </geometry>
    </collision>
  </link>
  <joint
    name="J_head_yaw"
    type="fixed">
    <origin
      xyz="0.009 0 0.4064"
      rpy="0 0 0" />
    <parent
      link="base_link" />
    <child
      link="Link_head_yaw" />
    <axis
      xyz="0 0 1" />
    <limit
      lower="-1.5708"
      upper="1.5708"
      effort="26"
      velocity="109.8" />
  </joint>
  <link
    name="Link_head_pitch">
    <inertial>
      <origin
        xyz="0.020569 0.033004 0.125"
        rpy="0 0 0" />
      <mass
        value="1.3943" />
      <inertia
        ixx="0.0060059"
        ixy="-9.4E-06"
        ixz="0.0007564"
        iyy="0.00629"
        iyz="-1.03E-05"
        izz="0.0048569" />
    </inertial>
    <visual>
      <origin
        xyz="0 0 0"
        rpy="0 0 0" />
      <geometry>
        <mesh
          filename="/home/pi/Downloads/OmniBotCtrl/resources/loong/meshes/Link_head_pitch.STL" />
      </geometry>
      <material
        name="">
        <color
          rgba="0.69804 0.69804 0.69804 1" />
      </material>
    </visual>
    <collision>
      <origin
        xyz="0 0 0"
        rpy="0 0 0" />
      <geometry>
        <mesh
          filename="/home/pi/Downloads/OmniBotCtrl/resources/loong/meshes/Link_head_pitch.STL" />
      </geometry>
    </collision>
  </link>
  <joint
    name="J_head_pitch"
    type="fixed">
    <origin
      xyz="0 -0.0345999999999997 0.0484999999999999"
      rpy="0 0 0" />
    <parent
      link="Link_head_yaw" />
    <child
      link="Link_head_pitch" />
    <axis
      xyz="0 1 0" />
    <limit
      lower="-0.7854"
      upper="0.7854"
      effort="26"
      velocity="109.8" />
  </joint>
  <link
    name="Link_waist_pitch">
    <inertial>
      <origin
        xyz="-0.00073496 0.049925 -2.9695E-05"
        rpy="0 0 0" />
      <mass
        value="2.6964" />
      <inertia
        ixx="0.0051971"
        ixy="4.37E-05"
        ixz="-3E-07"
        iyy="0.0047413"
        iyz="-6E-06"
        izz="0.0061906" />
    </inertial>
    <visual>
      <origin
        xyz="0 0 0"
        rpy="0 0 0" />
      <geometry>
        <mesh
          filename="/home/pi/Downloads/OmniBotCtrl/resources/loong/meshes/Link_waist_pitch.STL" />
      </geometry>
      <material
        name="">
        <color
          rgba="0.69804 0.69804 0.69804 1" />
      </material>
    </visual>
    <collision>
      <origin
        xyz="0 0 0"
        rpy="0 0 0" />
      <geometry>
        <mesh
          filename="/home/pi/Downloads/OmniBotCtrl/resources/loong/meshes/Link_waist_pitch.STL" />
      </geometry>
    </collision>
  </link>
  <joint
    name="J_waist_pitch"
    type="fixed">
    <origin
      xyz="0 -0.0655 0"
      rpy="0 0 0" />
    <parent
      link="base_link" />
    <child
      link="Link_waist_pitch" />
    <axis
      xyz="0 -1 0" />
    <limit
      lower="-0.29671"
      upper="0.78540"
      effort="315"
      velocity="3.72" />
  </joint>
  <link
    name="Link_waist_roll">
    <inertial>
      <origin
        xyz="-0.0037424 -0.001 -0.016856"
        rpy="0 0 0" />
      <mass
        value="2.9806" />
      <inertia
        ixx="0.0071327"
        ixy="0"
        ixz="0.00358"
        iyy="0.018825"
        iyz="0"
        izz="0.016056" />
    </inertial>
    <visual>
      <origin
        xyz="0 0 0"
        rpy="0 0 0" />
      <geometry>
        <mesh
          filename="/home/pi/Downloads/OmniBotCtrl/resources/loong/meshes/Link_waist_roll.STL" />
      </geometry>
      <material
        name="">
        <color
          rgba="0.8902 0.8902 0.91373 1" />
      </material>
    </visual>
    <collision>
      <origin
        xyz="0 0 0"
        rpy="0 0 0" />
      <geometry>
        <mesh
          filename="/home/pi/Downloads/OmniBotCtrl/resources/loong/meshes/Link_waist_roll.STL" />
      </geometry>
    </collision>
  </link>
  <joint
    name="J_waist_roll"
    type="fixed">
    <origin
      xyz="-0.064 0.0655 0"
      rpy="0 0 0" />
    <parent
      link="Link_waist_pitch" />
    <child
      link="Link_waist_roll" />
    <axis
      xyz="1 0 0" />
    <limit
      lower="-0.69813"
      upper="0.69813"
      effort="315"
      velocity="3.72" />
  </joint>
  <link
    name="Link_waist_yaw">
    <inertial>
      <origin
        xyz="-0.096172 -0.001 -0.057836"
        rpy="0 0 0" />
      <mass
        value="7.3588" />
      <inertia
        ixx="0.091635"
        ixy="0"
        ixz="-0.0058036"
        iyy="0.032766"
        iyz="0"
        izz="0.10764" />
    </inertial>
    <visual>
      <origin
        xyz="0 0 0"
        rpy="0 0 0" />
      <geometry>
        <mesh
          filename="/home/pi/Downloads/OmniBotCtrl/resources/loong/meshes/Link_waist_yaw.STL" />
      </geometry>
      <material
        name="">
        <color
          rgba="0.8902 0.8902 0.91373 1" />
      </material>
    </visual>
    <collision>
      <origin
        xyz="0 0 0"
        rpy="0 0 0" />
      <geometry>
        <mesh
          filename="/home/pi/Downloads/OmniBotCtrl/resources/loong/meshes/Link_waist_yaw.STL" />
      </geometry>
    </collision>
  </link>
  <joint
    name="J_waist_yaw"
    type="fixed">
    <origin
      xyz="0.0675 0 -0.098"
      rpy="0 0 0" />
    <parent
      link="Link_waist_roll" />
    <child
      link="Link_waist_yaw" />
    <axis
      xyz="0 0 1" />
    <limit
      lower="-0.78540"
      upper="0.78540"
      effort="121"
      velocity="5.92" />
  </joint>
  <link
    name="Link_hip_r_roll">
    <inertial>
      <origin
        xyz="0.075725 -0.0010616 0.016591"
        rpy="0 0 0" />
      <mass
        value="2.4334" />
      <inertia
        ixx="0.0036961"
        ixy="9E-07"
        ixz="-0.0001644"
        iyy="0.0045067"
        iyz="-6.3E-06"
        izz="0.0039063" />
    </inertial>
    <visual>
      <origin
        xyz="0 0 0"
        rpy="0 0 0" />
      <geometry>
        <mesh
          filename="/home/pi/Downloads/OmniBotCtrl/resources/loong/meshes/Link_hip_r_roll.STL" />
      </geometry>
      <material
        name="">
        <color
          rgba="0.89804 0.91765 0.92941 1" />
      </material>
    </visual>
    <collision>
      <origin
        xyz="0 0 0"
        rpy="0 0 0" />
      <geometry>
        <mesh
          filename="/home/pi/Downloads/OmniBotCtrl/resources/loong/meshes/Link_hip_r_roll.STL" />
      </geometry>
    </collision>
  </link>
  <joint
    name="J_hip_r_roll"
    type="revolute">
    <origin
      xyz="-0.0875 -0.12 -0.069"
      rpy="0 0 0" />
    <parent
      link="Link_waist_yaw" />
    <child
      link="Link_hip_r_roll" />
    <axis
      xyz="1 0 0" />
    <limit
      lower="-0.17453"
      upper="0.43633"
      effort="320"
      velocity="20.94" />
  </joint>
  <link
    name="Link_hip_r_yaw">
    <inertial>
      <origin
        xyz="-3.0911E-08 -0.0071356 -0.10063"
        rpy="0 0 0" />
      <mass
        value="3.4303" />
      <inertia
        ixx="0.0077365"
        ixy="0"
        ixz="0"
        iyy="0.0080807"
        iyz="-0.0001167"
        izz="0.006641" />
    </inertial>
    <visual>
      <origin
        xyz="0 0 0"
        rpy="0 0 0" />
      <geometry>
        <mesh
          filename="/home/pi/Downloads/OmniBotCtrl/resources/loong/meshes/Link_hip_r_yaw.STL" />
      </geometry>
      <material
        name="">
        <color
          rgba="0.89804 0.91765 0.92941 1" />
      </material>
    </visual>
    <collision>
      <origin
        xyz="0 0 0"
        rpy="0 0 0" />
      <geometry>
        <mesh
          filename="/home/pi/Downloads/OmniBotCtrl/resources/loong/meshes/Link_hip_r_yaw.STL" />
      </geometry>
    </collision>
  </link>
  <joint
    name="J_hip_r_yaw"
    type="revolute">
    <origin
      xyz="0.08225 0 -0.01"
      rpy="0 0 0" />
    <parent
      link="Link_hip_r_roll" />
    <child
      link="Link_hip_r_yaw" />
    <axis
      xyz="0 0 1" />
    <limit
      lower="-0.69813"
      upper="0.69813"
      effort="160"
      velocity="19.63" />
  </joint>
  <link
    name="Link_hip_r_pitch">
    <inertial>
      <origin
        xyz="0.0010856 -0.05497 -0.14535"
        rpy="0 0 0" />
      <mass
        value="5.2378" />
      <inertia
        ixx="0.043457"
        ixy="-0.0002478"
        ixz="0.0007626"
        iyy="0.037801"
        iyz="0.0007431"
        izz="0.015183" />
    </inertial>
    <visual>
      <origin
        xyz="0 0 0"
        rpy="0 0 0" />
      <geometry>
        <mesh
          filename="/home/pi/Downloads/OmniBotCtrl/resources/loong/meshes/Link_hip_r_pitch.STL" />
      </geometry>
      <material
        name="">
        <color
          rgba="0.69804 0.69804 0.69804 1" />
      </material>
    </visual>
    <collision>
      <origin
        xyz="0 0 0"
        rpy="0 0 0" />
      <geometry>
        <mesh
          filename="/home/pi/Downloads/OmniBotCtrl/resources/loong/meshes/Link_hip_r_pitch.STL" />
      </geometry>
    </collision>
  </link>
  <joint
    name="J_hip_r_pitch"
    type="revolute">
    <origin
      xyz="0 0.03675 -0.1055"
      rpy="0 0 0" />
    <parent
      link="Link_hip_r_yaw" />
    <child
      link="Link_hip_r_pitch" />
    <axis
      xyz="0 -1 0" />
    <limit
      lower="-0.78540"
      upper="1.83260"
      effort="396"
      velocity="19.16" />
  </joint>
  <link
    name="Link_knee_r_pitch">
    <inertial>
      <origin
        xyz="-0.0096425 2.9338E-06 -0.13601"
        rpy="0 0 0" />
      <mass
        value="2.9775" />
      <inertia
        ixx="0.02386"
        ixy="-6.76E-05"
        ixz="0.0004656"
        iyy="0.024184"
        iyz="0.0005481"
        izz="0.0023083" />
    </inertial>
    <visual>
      <origin
        xyz="0 0 0"
        rpy="0 0 0" />
      <geometry>
        <mesh
          filename="/home/pi/Downloads/OmniBotCtrl/resources/loong/meshes/Link_knee_r_pitch.STL" />
      </geometry>
      <material
        name="">
        <color
          rgba="0.66667 0.69804 0.76863 1" />
      </material>
    </visual>
    <collision>
      <origin
        xyz="0 0 0"
        rpy="0 0 0" />
      <geometry>
        <mesh
          filename="/home/pi/Downloads/OmniBotCtrl/resources/loong/meshes/Link_knee_r_pitch.STL" />
      </geometry>
    </collision>
  </link>
  <joint
    name="J_knee_r_pitch"
    type="revolute">
    <origin
      xyz="0 -0.01125 -0.4"
      rpy="0 0 0" />
    <parent
      link="Link_hip_r_pitch" />
    <child
      link="Link_knee_r_pitch" />
    <axis
      xyz="0 -1 0" />
    <limit
      lower="-2.35619"
      upper="0.08727"
      effort="396"
      velocity="19.16" />
  </joint>
  <link
    name="Link_ankle_r_pitch">
    <inertial>
      <origin
        xyz="-6.1835E-12 -1.2655E-07 -2.4682E-08"
        rpy="0 0 0" />
      <mass
        value="0.10145" />
      <inertia
        ixx="2.7175E-05"
        ixy="-1.0023E-14"
        ixz="8.1752E-13"
        iyy="6.1118E-06"
        iyz="-2.6285E-11"
        izz="2.6565E-05" />
    </inertial>
    <visual>
      <origin
        xyz="0 0 0"
        rpy="0 0 0" />
      <geometry>
        <mesh
          filename="/home/pi/Downloads/OmniBotCtrl/resources/loong/meshes/Link_ankle_r_pitch.STL" />
      </geometry>
      <material
        name="">
        <color
          rgba="0.52941 0.54902 0.54902 1" />
      </material>
    </visual>
    <!-- <collision>
      <origin
        xyz="0 0 0"
        rpy="0 0 0" />
      <geometry>
        <mesh
          filename="/home/pi/Downloads/OmniBotCtrl/resources/loong/meshes/Link_ankle_r_pitch.STL" />
      </geometry>
    </collision> -->
  </link>
  <joint
    name="J_ankle_r_pitch"
    type="revolute">
    <origin
      xyz="0 0 -0.387"
      rpy="0 0 0" />
    <parent
      link="Link_knee_r_pitch" />
    <child
      link="Link_ankle_r_pitch" />
    <axis
      xyz="0 -1 0" />
    <limit
      lower="-0.47"
      upper="0.87"
      effort="58.5"
      velocity="48.8" />
  </joint>
  <link
    name="Link_ankle1_r_roll">
    <inertial>
      <origin
        xyz="0.041078 -8.9152E-08 -0.043909"
        rpy="0 0 0" />
      <mass
        value="0.75229" />
      <inertia
        ixx="0.0004393"
        ixy="0"
        ixz="0.000269"
        iyy="0.0036465"
        iyz="0"
        izz="0.0036369" />
    </inertial>
    <visual>
      <origin
        xyz="0 0 0"
        rpy="0 0 0" />
      <geometry>
        <mesh
          filename="/home/pi/Downloads/OmniBotCtrl/resources/loong/meshes/Link_ankle_r_roll.STL" />
      </geometry>
      <material
        name="">
        <color
          rgba="0.89804 0.91765 0.92941 1" />
      </material>
    </visual>
    <!-- <collision>
      <origin
        xyz="0 0 0"
        rpy="0 0 0" />
      <geometry>
        <mesh
          filename="/home/pi/Downloads/OmniBotCtrl/resources/loong/meshes/Link_ankle_r_roll.STL" />
      </geometry>
    </collision> -->
             <collision>
            <origin rpy="0.00000000 1.5708 0.00000000" xyz="0.0485000 -0.04000000 -0.06300000"/>
            <geometry>
                <cylinder radius="0.00500000" length="0.2500000"/>
            </geometry>
    </collision>
    <collision>
    <origin rpy="0.00000000 1.5708 0.00000000" xyz="0.0485000 0.04000000 -0.06300000"/>
            <geometry>
                <!-- <sphere radius="0.02" /> -->
                <cylinder radius="0.00500000" length="0.2500000"/>
            </geometry>
    </collision>
  </link>
  <joint
    name="J_ankle_r_roll"
    type="revolute">
    <origin
      xyz="0 0 0"
      rpy="0 0 0" />
    <parent
      link="Link_ankle_r_pitch" />
    <child
      link="Link_ankle1_r_roll" />
    <axis
      xyz="1 0 0" />
    <limit
      lower="-0.43633"
      upper="0.43633"
      effort="58.5"
      velocity="48.8" />
  </joint>
  <link
    name="Link_hip_l_roll">
    <inertial>
      <origin
        xyz="0.075725 -0.00093843 0.016591"
        rpy="0 0 0" />
      <mass
        value="2.4334" />
      <inertia
        ixx="0.0034464"
        ixy="-9E-07"
        ixz="-0.0001904"
        iyy="0.0042569"
        iyz="6.6E-06"
        izz="0.0039063" />
    </inertial>
    <visual>
      <origin
        xyz="0 0 0"
        rpy="0 0 0" />
      <geometry>
        <mesh
          filename="/home/pi/Downloads/OmniBotCtrl/resources/loong/meshes/Link_hip_l_roll.STL" />
      </geometry>
      <material
        name="">
        <color
          rgba="0.89804 0.91765 0.92941 1" />
      </material>
    </visual>
    <collision>
      <origin
        xyz="0 0 0"
        rpy="0 0 0" />
      <geometry>
        <mesh
          filename="/home/pi/Downloads/OmniBotCtrl/resources/loong/meshes/Link_hip_l_roll.STL" />
      </geometry>
    </collision>
  </link>
  <joint
    name="J_hip_l_roll"
    type="revolute">
    <origin
      xyz="-0.0875 0.12 -0.069"
      rpy="0 0 0" />
    <parent
      link="Link_waist_yaw" />
    <child
      link="Link_hip_l_roll" />
    <axis
      xyz="1 0 0" />
    <limit
      lower="-0.17453"
      upper="0.43633"
      effort="320"
      velocity="20.94" />
  </joint>
  <link
    name="Link_hip_l_yaw">
    <inertial>
      <origin
        xyz="-3.1716E-08 0.0071358 -0.10063"
        rpy="0 0 0" />
      <mass
        value="3.4304" />
      <inertia
        ixx="0.0077365"
        ixy="0"
        ixz="0"
        iyy="0.0080807"
        iyz="0.0001167"
        izz="0.0066409" />
    </inertial>
    <visual>
      <origin
        xyz="0 0 0"
        rpy="0 0 0" />
      <geometry>
        <mesh
          filename="/home/pi/Downloads/OmniBotCtrl/resources/loong/meshes/Link_hip_l_yaw.STL" />
      </geometry>
      <material
        name="">
        <color
          rgba="0.89804 0.91765 0.92941 1" />
      </material>
    </visual>
    <collision>
      <origin
        xyz="0 0 0"
        rpy="0 0 0" />
      <geometry>
        <mesh
          filename="/home/pi/Downloads/OmniBotCtrl/resources/loong/meshes/Link_hip_l_yaw.STL" />
      </geometry>
    </collision>
  </link>
  <joint
    name="J_hip_l_yaw"
    type="revolute">
    <origin
      xyz="0.08225 0 -0.01"
      rpy="0 0 0" />
    <parent
      link="Link_hip_l_roll" />
    <child
      link="Link_hip_l_yaw" />
    <axis
      xyz="0 0 1" />
    <limit
      lower="-0.69813"
      upper="0.69813"
      effort="160"
      velocity="19.63" />
  </joint>
  <link
    name="Link_hip_l_pitch">
    <inertial>
      <origin
        xyz="0.0010856 0.05497 -0.14535"
        rpy="0 0 0" />
      <mass
        value="5.2378" />
      <inertia
        ixx="0.043457"
        ixy="0.0002479"
        ixz="0.0007626"
        iyy="0.037801"
        iyz="-0.0007431"
        izz="0.015183" />
    </inertial>
    <visual>
      <origin
        xyz="0 0 0"
        rpy="0 0 0" />
      <geometry>
        <mesh
          filename="/home/pi/Downloads/OmniBotCtrl/resources/loong/meshes/Link_hip_l_pitch.STL" />
      </geometry>
      <material
        name="">
        <color
          rgba="0.69804 0.69804 0.69804 1" />
      </material>
    </visual>
    <collision>
      <origin
        xyz="0 0 0"
        rpy="0 0 0" />
      <geometry>
        <mesh
          filename="/home/pi/Downloads/OmniBotCtrl/resources/loong/meshes/Link_hip_l_pitch.STL" />
      </geometry>
    </collision>
  </link>
  <joint
    name="J_hip_l_pitch"
    type="revolute">
    <origin
      xyz="0 -0.03675 -0.1055"
      rpy="0 0 0" />
    <parent
      link="Link_hip_l_yaw" />
    <child
      link="Link_hip_l_pitch" />
    <axis
      xyz="0 -1 0" />
    <limit
      lower="-0.78540"
      upper="1.83260"
      effort="396"
      velocity="19.16" />
  </joint>
  <link
    name="Link_knee_l_pitch">
    <inertial>
      <origin
        xyz="-0.0096425 -2.8684E-06 -0.13601"
        rpy="0 0 0" />
      <mass
        value="2.9775" />
      <inertia
        ixx="0.023859"
        ixy="6.76E-05"
        ixz="0.0004656"
        iyy="0.024183"
        iyz="-0.000548"
        izz="0.0023083" />
    </inertial>
    <visual>
      <origin
        xyz="0 0 0"
        rpy="0 0 0" />
      <geometry>
        <mesh
          filename="/home/pi/Downloads/OmniBotCtrl/resources/loong/meshes/Link_knee_l_pitch.STL" />
      </geometry>
      <material
        name="">
        <color
          rgba="0.66667 0.69804 0.76863 1" />
      </material>
    </visual>
    <collision>
      <origin
        xyz="0 0 0"
        rpy="0 0 0" />
      <geometry>
        <mesh
          filename="/home/pi/Downloads/OmniBotCtrl/resources/loong/meshes/Link_knee_l_pitch.STL" />
      </geometry>
    </collision>
  </link>
  <joint
    name="J_knee_l_pitch"
    type="revolute">
    <origin
      xyz="0 0.01125 -0.4"
      rpy="0 0 0" />
    <parent
      link="Link_hip_l_pitch" />
    <child
      link="Link_knee_l_pitch" />
    <axis
      xyz="0 -1 0" />
    <limit
      lower="-2.35619"
      upper="0.08727"
      effort="396"
      velocity="19.16" />
  </joint>
  <link
    name="Link_ankle_l_pitch">
    <inertial>
      <origin
        xyz="-6.1835E-12 1.2655E-07 6.7022E-08"
        rpy="0 0 0" />
      <mass
        value="0.10145" />
      <inertia
        ixx="2.7175E-05"
        ixy="1.0023E-14"
        ixz="8.1752E-13"
        iyy="6.1118E-06"
        iyz="2.6285E-11"
        izz="2.6565E-05" />
    </inertial>
    <visual>
      <origin
        xyz="0 0 0"
        rpy="0 0 0" />
      <geometry>
        <mesh
          filename="/home/pi/Downloads/OmniBotCtrl/resources/loong/meshes/Link_ankle_l_pitch.STL" />
      </geometry>
      <material
        name="">
        <color
          rgba="0.52941 0.54902 0.54902 1" />
      </material>
    </visual>
    <!-- <collision>
      <origin
        xyz="0 0 0"
        rpy="0 0 0" />
      <geometry>
        <mesh
          filename="/home/pi/Downloads/OmniBotCtrl/resources/loong/meshes/Link_ankle_l_pitch.STL" />
      </geometry>
    </collision> -->
  </link>
  <joint
    name="J_ankle_l_pitch"
    type="revolute">
    <origin
      xyz="0 0 -0.387"
      rpy="0 0 0" />
    <parent
      link="Link_knee_l_pitch" />
    <child
      link="Link_ankle_l_pitch" />
    <axis
      xyz="0 -1 0" />
    <limit
      lower="-0.47"
      upper="0.87"
      effort="58.5"
      velocity="48.8" />
  </joint>
  <link
    name="Link_ankle1_l_roll">
    <inertial>
      <origin
        xyz="0.041077 -2.9318E-08 -0.043909"
        rpy="0 0 0" />
      <mass
        value="0.7522882" />
      <inertia
        ixx="0.0004393"
        ixy="0"
        ixz="0.000269"
        iyy="0.0036465"
        iyz="0"
        izz="0.0036369" />
    </inertial>
    <visual>
      <origin
        xyz="0 0 0"
        rpy="0 0 0" />
      <geometry>
        <mesh
          filename="/home/pi/Downloads/OmniBotCtrl/resources/loong/meshes/Link_ankle_l_roll.STL" />
      </geometry>
      <material
        name="">
        <color
          rgba="0.89804 0.91765 0.92941 1" />
      </material>
    </visual>
    <!-- <collision>
      <origin
        xyz="0 0 0"
        rpy="0 0 0" />
      <geometry>
        <mesh
          filename="/home/pi/Downloads/OmniBotCtrl/resources/loong/meshes/Link_ankle_l_roll.STL" />
      </geometry>
    </collision> -->
    <collision>
            <origin rpy="0.00000000 1.5708 0.00000000" xyz="0.0485000 -0.04000000 -0.06300000"/>
            <geometry>
                <cylinder radius="0.00500000" length="0.2500000"/>
            </geometry>
    </collision>
    <collision>
    <origin rpy="0.00000000 1.5708 0.00000000" xyz="0.0485000 0.04000000 -0.06300000"/>
            <geometry>
                <!-- <sphere radius="0.02" /> -->
                <cylinder radius="0.00500000" length="0.2500000"/>
            </geometry>
    </collision>
  </link>
  <joint
    name="J_ankle_l_roll"
    type="revolute">
    <origin
      xyz="0 0 0"
      rpy="0 0 0" />
    <parent
      link="Link_ankle_l_pitch" />
    <child
      link="Link_ankle1_l_roll" />
    <axis
      xyz="1 0 0" />
    <limit
      lower="-0.43633"
      upper="0.43633"
      effort="58.5"
      velocity="48.8" />
  </joint>
</robot>
